Workbook

Sheet Данные
A1: ФИО менеджера | B1: ФИО клиента | C1: Дата сделки | D1: Сумма сделки | E1: NPS
A2: Белов Алексей Константинович | B2: Новикова Людмила Кирилловна | C2: 2023-09-01 | D2: 52260 | E2: 9
A3: Сидорова Елена Васильевна | B3: Волков Владимир Артемович | C3: 2023-09-04 | D3: 32372 | E3: 7
A4: Кузнецов Дмитрий Львович | B4: Смирнова Валерия Станиславовна | C4: 2023-09-04 | D4: 51312 | E4: 6
A5: Орлов Павел Денисович | B5: Алексеева Полина Викторовна | C5: 2023-09-04 | D5: 37796 | E5: 6
A6: Кузнецов Дмитрий Львович | B6: Петров Михаил Павлович | C6: 2023-09-04 | D6: 34852 | E6: 8
A7: Семенова Ирина Валерьевна | B7: Иванова Виктория Артемовна | C7: 2023-09-04 | D7: 53965 | E7: 6
A8: Белов Алексей Константинович | B8: Попова Светлана Геннадьевна | C8: 2023-09-04 | D8: 40844 | E8: 7
A9: Петров Владимир Кириллович | B9: Семенов Михаил Сергеевич | C9: 2023-09-04 | D9: 36221 | E9: 6
A10: Яковлев Артем Игоревич | B10: Смирнова Елена Олеговна | C10: 2023-09-05 | D10: 53891 | E10: 1
A11: Орлов Павел Денисович | B11: Степанова Людмила Ивановна | C11: 2023-09-05 | D11: 64414 | E11: 2
A12: Сидорова Елена Васильевна | B12: Федорова Екатерина Владимировна | C12: 2023-09-05 | D12: 64671 | E12: 7
A13: Ткаченко Андрей Олегович | B13: Семенов Михаил Сергеевич | C13: 2023-09-05 | D13: 90516 | E13: 7
... A1001: Фролов Сергей Викторович | B1001: Иванов Артем Павлович | C1001: 2024-09-02 | D1001: 59008 | E1001: 7

Sheet 1
A1: ФИО менеджера | D1: ФИО менеджера | E1: ФИО клиента | F1: Первый проект | G1: Последний проект | H1: Дни | J1: Менеджер Клиент | K1: ФИО менеджера | L1: ФИО клиента | M1: Дата сделки | N1: М&К | O1: ФИО менеджера | P1: ФИО клиента | Q1: Дата сделки
A2: Белов Алексей Константинович | D2: Белов Алексей Константинович | E2: Алексеев Егор Юрьевич | F2: =VLOOKUP(D2&E2,J:M,4,0) -> 2024-03-04 | G2: =VLOOKUP(D2&E2,N:Q,4,0) -> 2024-03-04 | H2: =G2-F2 -> 0 | J2: =K2&L2 -> Белов Алексей КонстантиновичНовикова Людмила Кирилловна | K2: Белов Алексей Константинович | L2: Новикова Людмила Кирилловна | M2: 2023-09-01 | N2: =O2&P2 -> Фролов Сергей ВикторовичПопов Иван Егорович | O2: Фролов Сергей Викторович | P2: Попов Иван Егорович | Q2: 2024-09-02
A3: Громова Мария Ильинична | D3: Белов Алексей Константинович | E3: Алексеев Михаил Алексеевич | F3: =VLOOKUP(D3&E3,J:M,4,0) -> 2024-03-11 | G3: =VLOOKUP(D3&E3,N:Q,4,0) -> 2024-03-11 | H3: =G3-F3 -> 0 | J3: =K3&L3 -> Сидорова Елена ВасильевнаВолков Владимир Артемович | K3: Сидорова Елена Васильевна | L3: Волков Владимир Артемович | M3: 2023-09-04 | N3: =O3&P3 -> Новикова Ольга ПетровнаЕгорова Юлия Никитична | O3: Новикова Ольга Петровна | P3: Егорова Юлия Никитична | Q3: 2024-09-02
A4: Иванова Анна Сергеевна | D4: Белов Алексей Константинович | E4: Алексеев Никита Алексеевич | F4: =VLOOKUP(D4&E4,J:M,4,0) -> 2024-05-15 | G4: =VLOOKUP(D4&E4,N:Q,4,0) -> 2024-05-15 | H4: =G4-F4 -> 0 | J4: =K4&L4 -> Кузнецов Дмитрий ЛьвовичСмирнова Валерия Станиславовна | K4: Кузнецов Дмитрий Львович | L4: Смирнова Валерия Станиславовна | M4: 2023-09-04 | N4: =O4&P4 -> Фролов Сергей ВикторовичПетров Никита Павлович | O4: Фролов Сергей Викторович | P4: Петров Никита Павлович | Q4: 2024-09-02
A5: Кузнецов Дмитрий Львович | D5: Белов Алексей Константинович | E5: Алексеева Ольга Дмитриевна | F5: =VLOOKUP(D5&E5,J:M,4,0) -> 2024-02-26 | G5: =VLOOKUP(D5&E5,N:Q,4,0) -> 2024-02-26 | H5: =G5-F5 -> 0 | J5: =K5&L5 -> Орлов Павел ДенисовичАлексеева Полина Викторовна | K5: Орлов Павел Денисович | L5: Алексеева Полина Викторовна | M5: 2023-09-04 | N5: =O5&P5 -> Петров Владимир КирилловичСидоров Егор Павлович | O5: Петров Владимир Кириллович | P5: Сидоров Егор Павлович | Q5: 2024-09-02
A6: Новикова Ольга Петровна | D6: Белов Алексей Константинович | E6: Васильев Егор Павлович | F6: =VLOOKUP(D6&E6,J:M,4,0) -> 2024-03-28 | G6: =VLOOKUP(D6&E6,N:Q,4,0) -> 2024-06-17 | H6: =G6-F6 -> 81 | J6: =K6&L6 -> Кузнецов Дмитрий ЛьвовичПетров Михаил Павлович | K6: Кузнецов Дмитрий Львович | L6: Петров Михаил Павлович | M6: 2023-09-04 | N6: =O6&P6 -> Фролов Сергей ВикторовичИванов Артем Павлович | O6: Фролов Сергей Викторович | P6: Иванов Артем Павлович | Q6: 2024-09-02
A7: Орлов Павел Денисович | D7: Белов Алексей Константинович | E7: Васильев Илья Алексеевич | F7: =VLOOKUP(D7&E7,J:M,4,0) -> 2024-04-25 | G7: =VLOOKUP(D7&E7,N:Q,4,0) -> 2024-04-25 | H7: =G7-F7 -> 0 | J7: =K7&L7 -> Семенова Ирина ВалерьевнаИванова Виктория Артемовна | K7: Семенова Ирина Валерьевна | L7: Иванова Виктория Артемовна | M7: 2023-09-04 | N7: =O7&P7 -> Яковлев Артем ИгоревичЕгорова Татьяна Ильинична | O7: Яковлев Артем Игоревич | P7: Егорова Татьяна Ильинична | Q7: 2024-08-30
A8: Петров Владимир Кириллович | D8: Белов Алексей Константинович | E8: Васильев Матвей Кириллович | F8: =VLOOKUP(D8&E8,J:M,4,0) -> 2024-01-17 | G8: =VLOOKUP(D8&E8,N:Q,4,0) -> 2024-01-17 | H8: =G8-F8 -> 0 | J8: =K8&L8 -> Белов Алексей КонстантиновичПопова Светлана Геннадьевна | K8: Белов Алексей Константинович | L8: Попова Светлана Геннадьевна | M8: 2023-09-04 | N8: =O8&P8 -> Семенова Ирина ВалерьевнаСидорова Ирина Кирилловна | O8: Семенова Ирина Валерьевна | P8: Сидорова Ирина Кирилловна | Q8: 2024-08-30
A9: Семенова Ирина Валерьевна | D9: Белов Алексей Константинович | E9: Васильева Виктория Артемовна | F9: =VLOOKUP(D9&E9,J:M,4,0) -> 2024-02-27 | G9: =VLOOKUP(D9&E9,N:Q,4,0) -> 2024-02-27 | H9: =G9-F9 -> 0 | J9: =K9&L9 -> Петров Владимир КирилловичСеменов Михаил Сергеевич | K9: Петров Владимир Кириллович | L9: Семенов Михаил Сергеевич | M9: 2023-09-04 | N9: =O9&P9 -> Иванова Анна СергеевнаПопова Наталья Станиславовна | O9: Иванова Анна Сергеевна | P9: Попова Наталья Станиславовна | Q9: 2024-08-29
A10: Сидорова Елена Васильевна | D10: Белов Алексей Константинович | E10: Васильева Елена Андреевна | F10: =VLOOKUP(D10&E10,J:M,4,0) -> 2023-10-23 | G10: =VLOOKUP(D10&E10,N:Q,4,0) -> 2024-04-15 | H10: =G10-F10 -> 175 | J10: =K10&L10 -> Яковлев Артем ИгоревичСмирнова Елена Олеговна | K10: Яковлев Артем Игоревич | L10: Смирнова Елена Олеговна | M10: 2023-09-05 | N10: =O10&P10 -> Петров Владимир КирилловичНиколаева Анна Михайловна | O10: Петров Владимир Кириллович | P10: Николаева Анна Михайловна | Q10: 2024-08-29
A11: Ткаченко Андрей Олегович | D11: Белов Алексей Константинович | E11: Васильева Юлия Сергеевна | F11: =VLOOKUP(D11&E11,J:M,4,0) -> 2024-03-11 | G11: =VLOOKUP(D11&E11,N:Q,4,0) -> 2024-03-11 | H11: =G11-F11 -> 0 | J11: =K11&L11 -> Орлов Павел ДенисовичСтепанова Людмила Ивановна | K11: Орлов Павел Денисович | L11: Степанова Людмила Ивановна | M11: 2023-09-05 | N11: =O11&P11 -> Яковлев Артем ИгоревичЕгорова Мария Кирилловна | O11: Яковлев Артем Игоревич | P11: Егорова Мария Кирилловна | Q11: 2024-08-29
A12: Фролов Сергей Викторович | D12: Белов Алексей Константинович | E12: Волков Владимир Артемович | F12: =VLOOKUP(D12&E12,J:M,4,0) -> 2023-11-03 | G12: =VLOOKUP(D12&E12,N:Q,4,0) -> 2023-11-03 | H12: =G12-F12 -> 0 | J12: =K12&L12 -> Сидорова Елена ВасильевнаФедорова Екатерина Владимировна | K12: Сидорова Елена Васильевна | L12: Федорова Екатерина Владимировна | M12: 2023-09-05 | N12: =O12&P12 -> Сидорова Елена ВасильевнаСтепанова Анна Романовна | O12: Сидорова Елена Васильевна | P12: Степанова Анна Романовна | Q12: 2024-08-29
A13: Яковлев Артем Игоревич | D13: Белов Алексей Константинович | E13: Волков Павел Иванович | F13: =VLOOKUP(D13&E13,J:M,4,0) -> 2024-04-04 | G13: =VLOOKUP(D13&E13,N:Q,4,0) -> 2024-08-02 | H13: =G13-F13 -> 120 | J13: =K13&L13 -> Ткаченко Андрей ОлеговичСеменов Михаил Сергеевич | K13: Ткаченко Андрей Олегович | L13: Семенов Михаил Сергеевич | M13: 2023-09-05 | N13: =O13&P13 -> Орлов Павел ДенисовичВасильев Егор Павлович | O13: Орлов Павел Денисович | P13: Васильев Егор Павлович | Q13: 2024-08-29
D14: Белов Алексей Константинович | E14: Волкова Светлана Ивановна | F14: =VLOOKUP(D14&E14,J:M,4,0) -> 2024-08-02 | G14: =VLOOKUP(D14&E14,N:Q,4,0) -> 2024-08-02 | H14: =G14-F14 -> 0 | J14: =K14&L14 -> Семенова Ирина ВалерьевнаВасильева Елена Андреевна | K14: Семенова Ирина Валерьевна | L14: Васильева Елена Андреевна | M14: 2023-09-05 | N14: =O14&P14 -> Новикова Ольга ПетровнаФедорова Людмила Сергеевна | O14: Новикова Ольга Петровна | P14: Федорова Людмила Сергеевна | Q14: 2024-08-28
D15: Белов Алексей Константинович | E15: Волкова София Александровна | F15: =VLOOKUP(D15&E15,J:M,4,0) -> 2024-02-21 | G15: =VLOOKUP(D15&E15,N:Q,4,0) -> 2024-02-21 | H15: =G15-F15 -> 0 | J15: =K15&L15 -> Ткаченко Андрей ОлеговичСмирнова Екатерина Ивановна | K15: Ткаченко Андрей Олегович | L15: Смирнова Екатерина Ивановна | M15: 2023-09-05 | N15: =O15&P15 -> Семенова Ирина ВалерьевнаАлексеева Светлана Артемовна | O15: Семенова Ирина Валерьевна | P15: Алексеева Светлана Артемовна | Q15: 2024-08-28
D16: Белов Алексей Константинович | E16: Егоров Илья Андреевич | F16: =VLOOKUP(D16&E16,J:M,4,0) -> 2023-11-30 | G16: =VLOOKUP(D16&E16,N:Q,4,0) -> 2024-07-08 | H16: =G16-F16 -> 221 | J16: =K16&L16 -> Новикова Ольга ПетровнаКузнецов Егор Андреевич | K16: Новикова Ольга Петровна | L16: Кузнецов Егор Андреевич | M16: 2023-09-06 | N16: =O16&P16 -> Яковлев Артем ИгоревичАлексеева Мария Олеговна | O16: Яковлев Артем Игоревич | P16: Алексеева Мария Олеговна | Q16: 2024-08-28
D17: Белов Алексей Константинович | E17: Егоров Никита Олегович | F17: =VLOOKUP(D17&E17,J:M,4,0) -> 2024-06-11 | G17: =VLOOKUP(D17&E17,N:Q,4,0) -> 2024-07-01 | H17: =G17-F17 -> 20 | J17: =K17&L17 -> Яковлев Артем ИгоревичОрлов Владимир Никитич | K17: Яковлев Артем Игоревич | L17: Орлов Владимир Никитич | M17: 2023-09-06 | N17: =O17&P17 -> Орлов Павел ДенисовичВасильев Егор Павлович | O17: Орлов Павел Денисович | P17: Васильев Егор Павлович | Q17: 2024-08-27
D18: Белов Алексей Константинович | E18: Егорова Юлия Никитична | F18: =VLOOKUP(D18&E18,J:M,4,0) -> 2024-07-17 | G18: =VLOOKUP(D18&E18,N:Q,4,0) -> 2024-07-17 | H18: =G18-F18 -> 0 | J18: =K18&L18 -> Петров Владимир КирилловичНовикова София Ивановна | K18: Петров Владимир Кириллович | L18: Новикова София Ивановна | M18: 2023-09-06 | N18: =O18&P18 -> Кузнецов Дмитрий ЛьвовичЛебедев Дмитрий Дмитриевич | O18: Кузнецов Дмитрий Львович | P18: Лебедев Дмитрий Дмитриевич | Q18: 2024-08-26
D19: Белов Алексей Константинович | E19: Козлов Роман Егорович | F19: =VLOOKUP(D19&E19,J:M,4,0) -> 2023-12-07 | G19: =VLOOKUP(D19&E19,N:Q,4,0) -> 2023-12-07 | H19: =G19-F19 -> 0 | J19: =K19&L19 -> Новикова Ольга ПетровнаСмирнова Екатерина Ивановна | K19: Новикова Ольга Петровна | L19: Смирнова Екатерина Ивановна | M19: 2023-09-06 | N19: =O19&P19 -> Фролов Сергей ВикторовичПопов Роман Владимирович | O19: Фролов Сергей Викторович | P19: Попов Роман Владимирович | Q19: 2024-08-26
D20: Белов Алексей Константинович | E20: Козлова Александра Андреевна | F20: =VLOOKUP(D20&E20,J:M,4,0) -> 2024-03-05 | G20: =VLOOKUP(D20&E20,N:Q,4,0) -> 2024-03-05 | H20: =G20-F20 -> 0 | J20: =K20&L20 -> Новикова Ольга ПетровнаКозлова Александра Андреевна | K20: Новикова Ольга Петровна | L20: Козлова Александра Андреевна | M20: 2023-09-07 | N20: =O20&P20 -> Иванова Анна СергеевнаСмирнова Екатерина Геннадьевна | O20: Иванова Анна Сергеевна | P20: Смирнова Екатерина Геннадьевна | Q20: 2024-08-26
D21: Белов Алексей Константинович | E21: Козлова Наталья Романовна | F21: =VLOOKUP(D21&E21,J:M,4,0) -> 2024-07-17 | G21: =VLOOKUP(D21&E21,N:Q,4,0) -> 2024-07-17 | H21: =G21-F21 -> 0 | J21: =K21&L21 -> Кузнецов Дмитрий ЛьвовичНовиков Иван Павлович | K21: Кузнецов Дмитрий Львович | L21: Новиков Иван Павлович | M21: 2023-09-07 | N21: =O21&P21 -> Новикова Ольга ПетровнаИванов Никита Романович | O21: Новикова Ольга Петровна | P21: Иванов Никита Романович | Q21: 2024-08-26
D22: Белов Алексей Константинович | E22: Кузнецов Алексей Олегович | F22: =VLOOKUP(D22&E22,J:M,4,0) -> 2024-06-21 | G22: =VLOOKUP(D22&E22,N:Q,4,0) -> 2024-06-21 | H22: =G22-F22 -> 0 | J22: =K22&L22 -> Орлов Павел ДенисовичОрлов Иван Викторович | K22: Орлов Павел Денисович | L22: Орлов Иван Викторович | M22: 2023-09-07 | N22: =O22&P22 -> Новикова Ольга ПетровнаСеменов Матвей Михайлович | O22: Новикова Ольга Петровна | P22: Семенов Матвей Михайлович | Q22: 2024-08-26
D23: Белов Алексей Константинович | E23: Кузнецов Иван Ильич | F23: =VLOOKUP(D23&E23,J:M,4,0) -> 2024-08-19 | G23: =VLOOKUP(D23&E23,N:Q,4,0) -> 2024-08-19 | H23: =G23-F23 -> 0 | J23: =K23&L23 -> Фролов Сергей ВикторовичПавлов Михаил Андреевич | K23: Фролов Сергей Викторович | L23: Павлов Михаил Андреевич | M23: 2023-09-07 | N23: =O23&P23 -> Ткаченко Андрей ОлеговичПавлова Ксения Романовна | O23: Ткаченко Андрей Олегович | P23: Павлова Ксения Романовна | Q23: 2024-08-23
D24: Белов Алексей Константинович | E24: Кузнецов Кирилл Павлович | F24: =VLOOKUP(D24&E24,J:M,4,0) -> 2024-01-09 | G24: =VLOOKUP(D24&E24,N:Q,4,0) -> 2024-01-09 | H24: =G24-F24 -> 0 | J24: =K24&L24 -> Новикова Ольга ПетровнаЛебедев Михаил Кириллович | K24: Новикова Ольга Петровна | L24: Лебедев Михаил Кириллович | M24: 2023-09-08 | N24: =O24&P24 -> Семенова Ирина ВалерьевнаНовикова Людмила Кирилловна | O24: Семенова Ирина Валерьевна | P24: Новикова Людмила Кирилловна | Q24: 2024-08-22
D25: Белов Алексей Константинович | E25: Кузнецов Павел Викторович | F25: =VLOOKUP(D25&E25,J:M,4,0) -> 2024-02-20 | G25: =VLOOKUP(D25&E25,N:Q,4,0) -> 2024-02-20 | H25: =G25-F25 -> 0 | J25: =K25&L25 -> Семенова Ирина ВалерьевнаВолкова Анна Викторовна | K25: Семенова Ирина Валерьевна | L25: Волкова Анна Викторовна | M25: 2023-09-08 | N25: =O25&P25 -> Громова Мария ИльиничнаЛебедева Анна Олеговна | O25: Громова Мария Ильинична | P25: Лебедева Анна Олеговна | Q25: 2024-08-22
... D790: Яковлев Артем Игоревич | E790: Федорова Екатерина Владимировна | F790: =VLOOKUP(D790&E790,J:M,4,0) -> 2024-08-19 | G790: =VLOOKUP(D790&E790,N:Q,4,0) -> 2024-08-19 | H790: =G790-F790 -> 0 | J790: =K790&L790 -> Новикова Ольга ПетровнаПопов Роман Владимирович | K790: Новикова Ольга Петровна | L790: Попов Роман Владимирович | M790: 2024-06-18 | N790: =O790&P790 -> Сидорова Елена ВасильевнаИванова Ольга Дмитриевна | O790: Сидорова Елена Васильевна | P790: Иванова Ольга Дмитриевна | Q790: 2023-11-15
J791: =K791&L791 -> Сидорова Елена ВасильевнаНовикова София Ивановна | K791: Сидорова Елена Васильевна | L791: Новикова София Ивановна | M791: 2024-06-18 | N791: =O791&P791 -> Кузнецов Дмитрий ЛьвовичПопов Георгий Егорович | O791: Кузнецов Дмитрий Львович | P791: Попов Георгий Егорович | Q791: 2023-11-14
J792: =K792&L792 -> Яковлев Артем ИгоревичСмирнова Екатерина Геннадьевна | K792: Яковлев Артем Игоревич | L792: Смирнова Екатерина Геннадьевна | M792: 2024-06-18 | N792: =O792&P792 -> Петров Владимир КирилловичАлексеева Мария Олеговна | O792: Петров Владимир Кириллович | P792: Алексеева Мария Олеговна | Q792: 2023-11-14
J793: =K793&L793 -> Сидорова Елена ВасильевнаПетров Павел Юрьевич | K793: Сидорова Елена Васильевна | L793: Петров Павел Юрьевич | M793: 2024-06-18 | N793: =O793&P793 -> Новикова Ольга ПетровнаПетров Михаил Павлович | O793: Новикова Ольга Петровна | P793: Петров Михаил Павлович | Q793: 2023-11-14
J794: =K794&L794 -> Иванова Анна СергеевнаСмирнова Елена Олеговна | K794: Иванова Анна Сергеевна | L794: Смирнова Елена Олеговна | M794: 2024-06-18 | N794: =O794&P794 -> Яковлев Артем ИгоревичКозлова Екатерина Викторовна | O794: Яковлев Артем Игоревич | P794: Козлова Екатерина Викторовна | Q794: 2023-11-14
J795: =K795&L795 -> Семенова Ирина ВалерьевнаИванов Георгий Павлович | K795: Семенова Ирина Валерьевна | L795: Иванов Георгий Павлович | M795: 2024-06-19 | N795: =O795&P795 -> Семенова Ирина ВалерьевнаОрлова Алиса Егоровна | O795: Семенова Ирина Валерьевна | P795: Орлова Алиса Егоровна | Q795: 2023-11-13
J796: =K796&L796 -> Сидорова Елена ВасильевнаКузнецов Кирилл Александрович | K796: Сидорова Елена Васильевна | L796: Кузнецов Кирилл Александрович | M796: 2024-06-21 | N796: =O796&P796 -> Ткаченко Андрей ОлеговичКозлов Илья Геннадьевич | O796: Ткаченко Андрей Олегович | P796: Козлов Илья Геннадьевич | Q796: 2023-11-13
J797: =K797&L797 -> Петров Владимир КирилловичВасильев Андрей Дмитриевич | K797: Петров Владимир Кириллович | L797: Васильев Андрей Дмитриевич | M797: 2024-06-21 | N797: =O797&P797 -> Ткаченко Андрей ОлеговичСеменова Полина Сергеевна | O797: Ткаченко Андрей Олегович | P797: Семенова Полина Сергеевна | Q797: 2023-11-13
J798: =K798&L798 -> Белов Алексей КонстантиновичКузнецов Алексей Олегович | K798: Белов Алексей Константинович | L798: Кузнецов Алексей Олегович | M798: 2024-06-21 | N798: =O798&P798 -> Орлов Павел ДенисовичИванов Георгий Павлович | O798: Орлов Павел Денисович | P798: Иванов Георгий Павлович | Q798: 2023-11-13
J799: =K799&L799 -> Орлов Павел ДенисовичВолкова Екатерина Егоровна | K799: Орлов Павел Денисович | L799: Волкова Екатерина Егоровна | M799: 2024-06-21 | N799: =O799&P799 -> Яковлев Артем ИгоревичПавлов Андрей Владимирович | O799: Яковлев Артем Игоревич | P799: Павлов Андрей Владимирович | Q799: 2023-11-13
J800: =K800&L800 -> Петров Владимир КирилловичКузнецов Егор Андреевич | K800: Петров Владимир Кириллович | L800: Кузнецов Егор Андреевич | M800: 2024-06-21 | N800: =O800&P800 -> Громова Мария ИльиничнаСтепанов Кирилл Алексеевич | O800: Громова Мария Ильинична | P800: Степанов Кирилл Алексеевич | Q800: 2023-11-13
J801: =K801&L801 -> Яковлев Артем ИгоревичЕгорова Татьяна Ильинична | K801: Яковлев Артем Игоревич | L801: Егорова Татьяна Ильинична | M801: 2024-06-24 | N801: =O801&P801 -> Ткаченко Андрей ОлеговичПопов Роман Владимирович | O801: Ткаченко Андрей Олегович | P801: Попов Роман Владимирович | Q801: 2023-11-13
J802: =K802&L802 -> Петров Владимир КирилловичПопова Полина Сергеевна | K802: Петров Владимир Кириллович | L802: Попова Полина Сергеевна | M802: 2024-06-24 | N802: =O802&P802 -> Петров Владимир КирилловичВолкова Анна Викторовна | O802: Петров Владимир Кириллович | P802: Волкова Анна Викторовна | Q802: 2023-11-10
... J1001: =K1001&L1001 -> Фролов Сергей ВикторовичИванов Артем Павлович | K1001: Фролов Сергей Викторович | L1001: Иванов Артем Павлович | M1001: 2024-09-02 | N1001: =O1001&P1001 -> Белов Алексей КонстантиновичНовикова Людмила Кирилловна | O1001: Белов Алексей Константинович | P1001: Новикова Людмила Кирилловна | Q1001: 2023-09-01

Sheet 1-1
A1: ФИО менеджера | B1: ФИО клиента | C1: Первый проект | D1: Последний проект | E1: Дни
A2: Яковлев Артем Игоревич | B2: Новикова София Ивановна | C2: 2023-09-19 | D2: 2024-08-15 | E2: 331
A3: Яковлев Артем Игоревич | B3: Попов Роман Владимирович | C3: 2023-09-21 | D3: 2024-08-16 | E3: 330
A4: Сидорова Елена Васильевна | B4: Семенова Александра Егоровна | C4: 2023-09-25 | D4: 2024-08-12 | E4: 322
A5: Фролов Сергей Викторович | B5: Павлов Михаил Андреевич | C5: 2023-09-07 | D5: 2024-07-22 | E5: 319
A6: Новикова Ольга Петровна | B6: Васильева Юлия Сергеевна | C6: 2023-09-11 | D6: 2024-07-25 | E6: 318
A7: Семенова Ирина Валерьевна | B7: Волкова Анна Викторовна | C7: 2023-09-08 | D7: 2024-07-16 | E7: 312
A8: Петров Владимир Кириллович | B8: Егоров Илья Ильич | C8: 2023-09-11 | D8: 2024-07-15 | E8: 308
A9: Орлов Павел Денисович | B9: Павлов Алексей Юрьевич | C9: 2023-09-28 | D9: 2024-07-31 | E9: 307
A10: Иванова Анна Сергеевна | B10: Сидоров Кирилл Михайлович | C10: 2023-10-17 | D10: 2024-08-05 | E10: 293
A11: Петров Владимир Кириллович | B11: Волкова Екатерина Егоровна | C11: 2023-11-06 | D11: 2024-08-14 | E11: 282
A12: Новикова Ольга Петровна | B12: Кузнецов Егор Андреевич | C12: 2023-09-06 | D12: 2024-06-13 | E12: 281
A13: Громова Мария Ильинична | B13: Попова Полина Сергеевна | C13: 2023-10-24 | D13: 2024-07-26 | E13: 276
... A790: Яковлев Артем Игоревич | B790: Федорова Екатерина Владимировна | C790: 2024-08-19 | D790: 2024-08-19 | E790: 0

Sheet 2
A1: Фио | B1: проекты | C1: сумма | D1: Менеджеры
A2: Алексеев Артур Артемович | B2: =COUNTIF(Данные!B:B,'2'!A129) -> 3 | C2: =SUMIF(Данные!B:B,'2'!A129,Данные!D:D) -> 81678 | D2: =COUNTIF('1'!E:E,'2'!A129) -> 3
A3: Алексеев Егор Юрьевич | B3: =COUNTIF(Данные!B:B,'2'!A130) -> 2 | C3: =SUMIF(Данные!B:B,'2'!A130,Данные!D:D) -> 166501 | D3: =COUNTIF('1'!E:E,'2'!A130) -> 2
A4: Алексеев Михаил Алексеевич | B4: =COUNTIF(Данные!B:B,'2'!A56) -> 3 | C4: =SUMIF(Данные!B:B,'2'!A56,Данные!D:D) -> 168111 | D4: =COUNTIF('1'!E:E,'2'!A56) -> 3
A5: Алексеев Никита Алексеевич | B5: =COUNTIF(Данные!B:B,'2'!A116) -> 3 | C5: =SUMIF(Данные!B:B,'2'!A116,Данные!D:D) -> 194688 | D5: =COUNTIF('1'!E:E,'2'!A116) -> 2
A6: Алексеева Валерия Викторовна | B6: =COUNTIF(Данные!B:B,'2'!A64) -> 7 | C6: =SUMIF(Данные!B:B,'2'!A64,Данные!D:D) -> 319100 | D6: =COUNTIF('1'!E:E,'2'!A64) -> 6
A7: Алексеева Мария Олеговна | B7: =COUNTIF(Данные!B:B,'2'!A45) -> 2 | C7: =SUMIF(Данные!B:B,'2'!A45,Данные!D:D) -> 129384 | D7: =COUNTIF('1'!E:E,'2'!A45) -> 2
A8: Алексеева Ольга Дмитриевна | B8: =COUNTIF(Данные!B:B,'2'!A169) -> 5 | C8: =SUMIF(Данные!B:B,'2'!A169,Данные!D:D) -> 377895 | D8: =COUNTIF('1'!E:E,'2'!A169) -> 4
A9: Алексеева Полина Викторовна | B9: =COUNTIF(Данные!B:B,'2'!A5) -> 7 | C9: =SUMIF(Данные!B:B,'2'!A5,Данные!D:D) -> 153508 | D9: =COUNTIF('1'!E:E,'2'!A5) -> 6
A10: Алексеева Полина Сергеевна | B10: =COUNTIF(Данные!B:B,'2'!A185) -> 3 | C10: =SUMIF(Данные!B:B,'2'!A185,Данные!D:D) -> 169307 | D10: =COUNTIF('1'!E:E,'2'!A185) -> 3
A11: Алексеева Светлана Артемовна | B11: =COUNTIF(Данные!B:B,'2'!A66) -> 4 | C11: =SUMIF(Данные!B:B,'2'!A66,Данные!D:D) -> 204579 | D11: =COUNTIF('1'!E:E,'2'!A66) -> 3
A12: Алексеева Юлия Никитична | B12: =COUNTIF(Данные!B:B,'2'!A62) -> 2 | C12: =SUMIF(Данные!B:B,'2'!A62,Данные!D:D) -> 110354 | D12: =COUNTIF('1'!E:E,'2'!A62) -> 1
A13: Васильев Андрей Дмитриевич | B13: =COUNTIF(Данные!B:B,'2'!A117) -> 3 | C13: =SUMIF(Данные!B:B,'2'!A117,Данные!D:D) -> 193948 | D13: =COUNTIF('1'!E:E,'2'!A117) -> 3
A14: Васильев Андрей Павлович | B14: =COUNTIF(Данные!B:B,'2'!A102) -> 6 | C14: =SUMIF(Данные!B:B,'2'!A102,Данные!D:D) -> 286452 | D14: =COUNTIF('1'!E:E,'2'!A102) -> 6
A15: Васильев Владимир Алексеевич | B15: =COUNTIF(Данные!B:B,'2'!A43) -> 8 | C15: =SUMIF(Данные!B:B,'2'!A43,Данные!D:D) -> 531961 | D15: =COUNTIF('1'!E:E,'2'!A43) -> 6
A16: Васильев Егор Павлович | B16: =COUNTIF(Данные!B:B,'2'!A41) -> 3 | C16: =SUMIF(Данные!B:B,'2'!A41,Данные!D:D) -> 81576 | D16: =COUNTIF('1'!E:E,'2'!A41) -> 1
A17: Васильев Илья Алексеевич | B17: =COUNTIF(Данные!B:B,'2'!A147) -> 9 | C17: =SUMIF(Данные!B:B,'2'!A147,Данные!D:D) -> 553605 | D17: =COUNTIF('1'!E:E,'2'!A147) -> 6
A18: Васильев Матвей Кириллович | B18: =COUNTIF(Данные!B:B,'2'!A162) -> 1 | C18: =SUMIF(Данные!B:B,'2'!A162,Данные!D:D) -> 41661 | D18: =COUNTIF('1'!E:E,'2'!A162) -> 1
A19: Васильева Виктория Артемовна | B19: =COUNTIF(Данные!B:B,'2'!A164) -> 6 | C19: =SUMIF(Данные!B:B,'2'!A164,Данные!D:D) -> 286243 | D19: =COUNTIF('1'!E:E,'2'!A164) -> 4
A20: Васильева Дарья Андреевна | B20: =COUNTIF(Данные!B:B,'2'!A34) -> 4 | C20: =SUMIF(Данные!B:B,'2'!A34,Данные!D:D) -> 196778 | D20: =COUNTIF('1'!E:E,'2'!A34) -> 3
A21: Васильева Елена Андреевна | B21: =COUNTIF(Данные!B:B,'2'!A13) -> 10 | C21: =SUMIF(Данные!B:B,'2'!A13,Данные!D:D) -> 585025 | D21: =COUNTIF('1'!E:E,'2'!A13) -> 5
A22: Васильева Ксения Егоровна | B22: =COUNTIF(Данные!B:B,'2'!A144) -> 5 | C22: =SUMIF(Данные!B:B,'2'!A144,Данные!D:D) -> 319058 | D22: =COUNTIF('1'!E:E,'2'!A144) -> 4
A23: Васильева Юлия Сергеевна | B23: =COUNTIF(Данные!B:B,'2'!A30) -> 3 | C23: =SUMIF(Данные!B:B,'2'!A30,Данные!D:D) -> 83517 | D23: =COUNTIF('1'!E:E,'2'!A30) -> 3
A24: Волков Алексей Никитич | B24: =COUNTIF(Данные!B:B,'2'!A127) -> 6 | C24: =SUMIF(Данные!B:B,'2'!A127,Данные!D:D) -> 251010 | D24: =COUNTIF('1'!E:E,'2'!A127) -> 5
A25: Волков Владимир Артемович | B25: =COUNTIF(Данные!B:B,'2'!A3) -> 10 | C25: =SUMIF(Данные!B:B,'2'!A3,Данные!D:D) -> 531637 | D25: =COUNTIF('1'!E:E,'2'!A3) -> 7
A26: Волков Павел Иванович | B26: =COUNTIF(Данные!B:B,'2'!A47) -> 8 | C26: =SUMIF(Данные!B:B,'2'!A47,Данные!D:D) -> 468679 | D26: =COUNTIF('1'!E:E,'2'!A47) -> 6
A27: Волкова Анна Викторовна | B27: =COUNTIF(Данные!B:B,'2'!A23) -> 4 | C27: =SUMIF(Данные!B:B,'2'!A23,Данные!D:D) -> 163291 | D27: =COUNTIF('1'!E:E,'2'!A23) -> 3
A28: Волкова Анна Станиславовна | B28: =COUNTIF(Данные!B:B,'2'!A33) -> 5 | C28: =SUMIF(Данные!B:B,'2'!A33,Данные!D:D) -> 246935 | D28: =COUNTIF('1'!E:E,'2'!A33) -> 4
A29: Волкова Виктория Артемовна | B29: =COUNTIF(Данные!B:B,'2'!A108) -> 1 | C29: =SUMIF(Данные!B:B,'2'!A108,Данные!D:D) -> 66499 | D29: =COUNTIF('1'!E:E,'2'!A108) -> 1
A30: Волкова Виктория Павловна | B30: =COUNTIF(Данные!B:B,'2'!A171) -> 5 | C30: =SUMIF(Данные!B:B,'2'!A171,Данные!D:D) -> 237057 | D30: =COUNTIF('1'!E:E,'2'!A171) -> 5
A31: Волкова Дарья Владимировна | B31: =COUNTIF(Данные!B:B,'2'!A76) -> 3 | C31: =SUMIF(Данные!B:B,'2'!A76,Данные!D:D) -> 226438 | D31: =COUNTIF('1'!E:E,'2'!A76) -> 2
A32: Волкова Екатерина Егоровна | B32: =COUNTIF(Данные!B:B,'2'!A35) -> 8 | C32: =SUMIF(Данные!B:B,'2'!A35,Данные!D:D) -> 453025 | D32: =COUNTIF('1'!E:E,'2'!A35) -> 6
A33: Волкова Людмила Кирилловна | B33: =COUNTIF(Данные!B:B,'2'!A94) -> 7 | C33: =SUMIF(Данные!B:B,'2'!A94,Данные!D:D) -> 423478 | D33: =COUNTIF('1'!E:E,'2'!A94) -> 5
A34: Волкова Полина Юрьевна | B34: =COUNTIF(Данные!B:B,'2'!A158) -> 5 | C34: =SUMIF(Данные!B:B,'2'!A158,Данные!D:D) -> 286001 | D34: =COUNTIF('1'!E:E,'2'!A158) -> 5
A35: Волкова Светлана Ивановна | B35: =COUNTIF(Данные!B:B,'2'!A40) -> 4 | C35: =SUMIF(Данные!B:B,'2'!A40,Данные!D:D) -> 203817 | D35: =COUNTIF('1'!E:E,'2'!A40) -> 3
A36: Волкова София Александровна | B36: =COUNTIF(Данные!B:B,'2'!A75) -> 4 | C36: =SUMIF(Данные!B:B,'2'!A75,Данные!D:D) -> 236139 | D36: =COUNTIF('1'!E:E,'2'!A75) -> 4
A37: Егоров Алексей Михайлович | B37: =COUNTIF(Данные!B:B,'2'!A72) -> 11 | C37: =SUMIF(Данные!B:B,'2'!A72,Данные!D:D) -> 650682 | D37: =COUNTIF('1'!E:E,'2'!A72) -> 7
A38: Егоров Андрей Егорович | B38: =COUNTIF(Данные!B:B,'2'!A123) -> 3 | C38: =SUMIF(Данные!B:B,'2'!A123,Данные!D:D) -> 188512 | D38: =COUNTIF('1'!E:E,'2'!A123) -> 3
A39: Егоров Иван Андреевич | B39: =COUNTIF(Данные!B:B,'2'!A126) -> 1 | C39: =SUMIF(Данные!B:B,'2'!A126,Данные!D:D) -> 49077 | D39: =COUNTIF('1'!E:E,'2'!A126) -> 1
A40: Егоров Илья Андреевич | B40: =COUNTIF(Данные!B:B,'2'!A145) -> 7 | C40: =SUMIF(Данные!B:B,'2'!A145,Данные!D:D) -> 287789 | D40: =COUNTIF('1'!E:E,'2'!A145) -> 4
...

Sheet 3-данные
A1: ФИО менеджера | B1: ФИО клиента | C1: Дата сделки | D1: Сумма сделки | E1: NPS | F1: Год | G1: Месяц | H1: Год&Месяц
A2: Белов Алексей Константинович | B2: Новикова Людмила Кирилловна | C2: 2023-09-01 | D2: 52260 | E2: 9 | F2: =YEAR(C2) -> 2023 | G2: =MONTH(C2) -> 9 | H2: =F2&"-"&G2 -> 2023-9
A3: Сидорова Елена Васильевна | B3: Волков Владимир Артемович | C3: 2023-09-04 | D3: 32372 | E3: 7 | F3: =YEAR(C3) -> 2023 | G3: =MONTH(C3) -> 9 | H3: =F3&"-"&G3 -> 2023-9
A4: Кузнецов Дмитрий Львович | B4: Смирнова Валерия Станиславовна | C4: 2023-09-04 | D4: 51312 | E4: 6 | F4: =YEAR(C4) -> 2023 | G4: =MONTH(C4) -> 9 | H4: =F4&"-"&G4 -> 2023-9
A5: Орлов Павел Денисович | B5: Алексеева Полина Викторовна | C5: 2023-09-04 | D5: 37796 | E5: 6 | F5: =YEAR(C5) -> 2023 | G5: =MONTH(C5) -> 9 | H5: =F5&"-"&G5 -> 2023-9
A6: Кузнецов Дмитрий Львович | B6: Петров Михаил Павлович | C6: 2023-09-04 | D6: 34852 | E6: 8 | F6: =YEAR(C6) -> 2023 | G6: =MONTH(C6) -> 9 | H6: =F6&"-"&G6 -> 2023-9
A7: Семенова Ирина Валерьевна | B7: Иванова Виктория Артемовна | C7: 2023-09-04 | D7: 53965 | E7: 6 | F7: =YEAR(C7) -> 2023 | G7: =MONTH(C7) -> 9 | H7: =F7&"-"&G7 -> 2023-9
A8: Белов Алексей Константинович | B8: Попова Светлана Геннадьевна | C8: 2023-09-04 | D8: 40844 | E8: 7 | F8: =YEAR(C8) -> 2023 | G8: =MONTH(C8) -> 9 | H8: =F8&"-"&G8 -> 2023-9
A9: Петров Владимир Кириллович | B9: Семенов Михаил Сергеевич | C9: 2023-09-04 | D9: 36221 | E9: 6 | F9: =YEAR(C9) -> 2023 | G9: =MONTH(C9) -> 9 | H9: =F9&"-"&G9 -> 2023-9
A10: Яковлев Артем Игоревич | B10: Смирнова Елена Олеговна | C10: 2023-09-05 | D10: 53891 | E10: 1 | F10: =YEAR(C10) -> 2023 | G10: =MONTH(C10) -> 9 | H10: =F10&"-"&G10 -> 2023-9
A11: Орлов Павел Денисович | B11: Степанова Людмила Ивановна | C11: 2023-09-05 | D11: 64414 | E11: 2 | F11: =YEAR(C11) -> 2023 | G11: =MONTH(C11) -> 9 | H11: =F11&"-"&G11 -> 2023-9
A12: Сидорова Елена Васильевна | B12: Федорова Екатерина Владимировна | C12: 2023-09-05 | D12: 64671 | E12: 7 | F12: =YEAR(C12) -> 2023 | G12: =MONTH(C12) -> 9 | H12: =F12&"-"&G12 -> 2023-9
A13: Ткаченко Андрей Олегович | B13: Семенов Михаил Сергеевич | C13: 2023-09-05 | D13: 90516 | E13: 7 | F13: =YEAR(C13) -> 2023 | G13: =MONTH(C13) -> 9 | H13: =F13&"-"&G13 -> 2023-9
... A1001: Фролов Сергей Викторович | B1001: Иванов Артем Павлович | C1001: 2024-09-02 | D1001: 59008 | E1001: 7 | F1001: =YEAR(C1001) -> 2024 | G1001: =MONTH(C1001) -> 9 | H1001: =F1001&"-"&G1001 -> 2024-9

Sheet 3
A1: ФИО Менеджера (по алфавиту) | B1: 2023-9 | C1: 2023-10 | D1: 2023-11 | E1: 2023-12 | F1: 2024-1 | G1: 2024-2 | H1: 2024-3 | I1: 2024-4 | J1: 2024-5 | K1: 2024-6 | L1: 2024-7 | M1: 2024-8 | N1: 2024-9
A2: Белов Алексей Константинович | B2: =COUNTIFS('3-данные'!$A:$A,'3'!$A2,'3-данные'!$H:$H,'3'!B$1) -> 6 | C2: =COUNTIFS('3-данные'!$A:$A,'3'!$A2,'3-данные'!$H:$H,'3'!C$1) -> 7 | D2: =COUNTIFS('3-данные'!$A:$A,'3'!$A2,'3-данные'!$H:$H,'3'!D$1) -> 7 | E2: =COUNTIFS('3-данные'!$A:$A,'3'!$A2,'3-данные'!$H:$H,'3'!E$1) -> 3 | F2: =COUNTIFS('3-данные'!$A:$A,'3'!$A2,'3-данные'!$H:$H,'3'!F$1) -> 9 | G2: =COUNTIFS('3-данные'!$A:$A,'3'!$A2,'3-данные'!$H:$H,'3'!G$1) -> 7 | H2: =COUNTIFS('3-данные'!$A:$A,'3'!$A2,'3-данные'!$H:$H,'3'!H$1) -> 11 | I2: =COUNTIFS('3-данные'!$A:$A,'3'!$A2,'3-данные'!$H:$H,'3'!I$1) -> 7 | ... N2: =COUNTIFS('3-данные'!$A:$A,'3'!$A2,'3-данные'!$H:$H,'3'!N$1) -> 0
A3: Громова Мария Ильинична | B3: =COUNTIFS('3-данные'!$A:$A,'3'!$A3,'3-данные'!$H:$H,'3'!B$1) -> 5 | C3: =COUNTIFS('3-данные'!$A:$A,'3'!$A3,'3-данные'!$H:$H,'3'!C$1) -> 7 | D3: =COUNTIFS('3-данные'!$A:$A,'3'!$A3,'3-данные'!$H:$H,'3'!D$1) -> 7 | E3: =COUNTIFS('3-данные'!$A:$A,'3'!$A3,'3-данные'!$H:$H,'3'!E$1) -> 6 | F3: =COUNTIFS('3-данные'!$A:$A,'3'!$A3,'3-данные'!$H:$H,'3'!F$1) -> 6 | G3: =COUNTIFS('3-данные'!$A:$A,'3'!$A3,'3-данные'!$H:$H,'3'!G$1) -> 5 | H3: =COUNTIFS('3-данные'!$A:$A,'3'!$A3,'3-данные'!$H:$H,'3'!H$1) -> 11 | I3: =COUNTIFS('3-данные'!$A:$A,'3'!$A3,'3-данные'!$H:$H,'3'!I$1) -> 5 | ... N3: =COUNTIFS('3-данные'!$A:$A,'3'!$A3,'3-данные'!$H:$H,'3'!N$1) -> 0
A4: Иванова Анна Сергеевна | B4: =COUNTIFS('3-данные'!$A:$A,'3'!$A4,'3-данные'!$H:$H,'3'!B$1) -> 4 | C4: =COUNTIFS('3-данные'!$A:$A,'3'!$A4,'3-данные'!$H:$H,'3'!C$1) -> 11 | D4: =COUNTIFS('3-данные'!$A:$A,'3'!$A4,'3-данные'!$H:$H,'3'!D$1) -> 8 | E4: =COUNTIFS('3-данные'!$A:$A,'3'!$A4,'3-данные'!$H:$H,'3'!E$1) -> 3 | F4: =COUNTIFS('3-данные'!$A:$A,'3'!$A4,'3-данные'!$H:$H,'3'!F$1) -> 7 | G4: =COUNTIFS('3-данные'!$A:$A,'3'!$A4,'3-данные'!$H:$H,'3'!G$1) -> 7 | H4: =COUNTIFS('3-данные'!$A:$A,'3'!$A4,'3-данные'!$H:$H,'3'!H$1) -> 2 | I4: =COUNTIFS('3-данные'!$A:$A,'3'!$A4,'3-данные'!$H:$H,'3'!I$1) -> 6 | ... N4: =COUNTIFS('3-данные'!$A:$A,'3'!$A4,'3-данные'!$H:$H,'3'!N$1) -> 0
A5: Кузнецов Дмитрий Львович | B5: =COUNTIFS('3-данные'!$A:$A,'3'!$A5,'3-данные'!$H:$H,'3'!B$1) -> 10 | C5: =COUNTIFS('3-данные'!$A:$A,'3'!$A5,'3-данные'!$H:$H,'3'!C$1) -> 9 | D5: =COUNTIFS('3-данные'!$A:$A,'3'!$A5,'3-данные'!$H:$H,'3'!D$1) -> 4 | E5: =COUNTIFS('3-данные'!$A:$A,'3'!$A5,'3-данные'!$H:$H,'3'!E$1) -> 5 | F5: =COUNTIFS('3-данные'!$A:$A,'3'!$A5,'3-данные'!$H:$H,'3'!F$1) -> 10 | G5: =COUNTIFS('3-данные'!$A:$A,'3'!$A5,'3-данные'!$H:$H,'3'!G$1) -> 8 | H5: =COUNTIFS('3-данные'!$A:$A,'3'!$A5,'3-данные'!$H:$H,'3'!H$1) -> 8 | I5: =COUNTIFS('3-данные'!$A:$A,'3'!$A5,'3-данные'!$H:$H,'3'!I$1) -> 7 | ... N5: =COUNTIFS('3-данные'!$A:$A,'3'!$A5,'3-данные'!$H:$H,'3'!N$1) -> 0
A6: Новикова Ольга Петровна | B6: =COUNTIFS('3-данные'!$A:$A,'3'!$A6,'3-данные'!$H:$H,'3'!B$1) -> 8 | C6: =COUNTIFS('3-данные'!$A:$A,'3'!$A6,'3-данные'!$H:$H,'3'!C$1) -> 5 | D6: =COUNTIFS('3-данные'!$A:$A,'3'!$A6,'3-данные'!$H:$H,'3'!D$1) -> 6 | E6: =COUNTIFS('3-данные'!$A:$A,'3'!$A6,'3-данные'!$H:$H,'3'!E$1) -> 5 | F6: =COUNTIFS('3-данные'!$A:$A,'3'!$A6,'3-данные'!$H:$H,'3'!F$1) -> 7 | G6: =COUNTIFS('3-данные'!$A:$A,'3'!$A6,'3-данные'!$H:$H,'3'!G$1) -> 4 | H6: =COUNTIFS('3-данные'!$A:$A,'3'!$A6,'3-данные'!$H:$H,'3'!H$1) -> 5 | I6: =COUNTIFS('3-данные'!$A:$A,'3'!$A6,'3-данные'!$H:$H,'3'!I$1) -> 7 | ... N6: =COUNTIFS('3-данные'!$A:$A,'3'!$A6,'3-данные'!$H:$H,'3'!N$1) -> 1
A7: Орлов Павел Денисович | B7: =COUNTIFS('3-данные'!$A:$A,'3'!$A7,'3-данные'!$H:$H,'3'!B$1) -> 8 | C7: =COUNTIFS('3-данные'!$A:$A,'3'!$A7,'3-данные'!$H:$H,'3'!C$1) -> 5 | D7: =COUNTIFS('3-данные'!$A:$A,'3'!$A7,'3-данные'!$H:$H,'3'!D$1) -> 9 | E7: =COUNTIFS('3-данные'!$A:$A,'3'!$A7,'3-данные'!$H:$H,'3'!E$1) -> 12 | F7: =COUNTIFS('3-данные'!$A:$A,'3'!$A7,'3-данные'!$H:$H,'3'!F$1) -> 9 | G7: =COUNTIFS('3-данные'!$A:$A,'3'!$A7,'3-данные'!$H:$H,'3'!G$1) -> 6 | H7: =COUNTIFS('3-данные'!$A:$A,'3'!$A7,'3-данные'!$H:$H,'3'!H$1) -> 8 | I7: =COUNTIFS('3-данные'!$A:$A,'3'!$A7,'3-данные'!$H:$H,'3'!I$1) -> 7 | ... N7: =COUNTIFS('3-данные'!$A:$A,'3'!$A7,'3-данные'!$H:$H,'3'!N$1) -> 0
A8: Петров Владимир Кириллович | B8: =COUNTIFS('3-данные'!$A:$A,'3'!$A8,'3-данные'!$H:$H,'3'!B$1) -> 9 | C8: =COUNTIFS('3-данные'!$A:$A,'3'!$A8,'3-данные'!$H:$H,'3'!C$1) -> 7 | D8: =COUNTIFS('3-данные'!$A:$A,'3'!$A8,'3-данные'!$H:$H,'3'!D$1) -> 10 | E8: =COUNTIFS('3-данные'!$A:$A,'3'!$A8,'3-данные'!$H:$H,'3'!E$1) -> 6 | F8: =COUNTIFS('3-данные'!$A:$A,'3'!$A8,'3-данные'!$H:$H,'3'!F$1) -> 12 | G8: =COUNTIFS('3-данные'!$A:$A,'3'!$A8,'3-данные'!$H:$H,'3'!G$1) -> 6 | H8: =COUNTIFS('3-данные'!$A:$A,'3'!$A8,'3-данные'!$H:$H,'3'!H$1) -> 4 | I8: =COUNTIFS('3-данные'!$A:$A,'3'!$A8,'3-данные'!$H:$H,'3'!I$1) -> 16 | ... N8: =COUNTIFS('3-данные'!$A:$A,'3'!$A8,'3-данные'!$H:$H,'3'!N$1) -> 1
A9: Семенова Ирина Валерьевна | B9: =COUNTIFS('3-данные'!$A:$A,'3'!$A9,'3-данные'!$H:$H,'3'!B$1) -> 8 | C9: =COUNTIFS('3-данные'!$A:$A,'3'!$A9,'3-данные'!$H:$H,'3'!C$1) -> 7 | D9: =COUNTIFS('3-данные'!$A:$A,'3'!$A9,'3-данные'!$H:$H,'3'!D$1) -> 8 | E9: =COUNTIFS('3-данные'!$A:$A,'3'!$A9,'3-данные'!$H:$H,'3'!E$1) -> 4 | F9: =COUNTIFS('3-данные'!$A:$A,'3'!$A9,'3-данные'!$H:$H,'3'!F$1) -> 6 | G9: =COUNTIFS('3-данные'!$A:$A,'3'!$A9,'3-данные'!$H:$H,'3'!G$1) -> 9 | H9: =COUNTIFS('3-данные'!$A:$A,'3'!$A9,'3-данные'!$H:$H,'3'!H$1) -> 6 | I9: =COUNTIFS('3-данные'!$A:$A,'3'!$A9,'3-данные'!$H:$H,'3'!I$1) -> 8 | ... N9: =COUNTIFS('3-данные'!$A:$A,'3'!$A9,'3-данные'!$H:$H,'3'!N$1) -> 0
A10: Сидорова Елена Васильевна | B10: =COUNTIFS('3-данные'!$A:$A,'3'!$A10,'3-данные'!$H:$H,'3'!B$1) -> 9 | C10: =COUNTIFS('3-данные'!$A:$A,'3'!$A10,'3-данные'!$H:$H,'3'!C$1) -> 7 | D10: =COUNTIFS('3-данные'!$A:$A,'3'!$A10,'3-данные'!$H:$H,'3'!D$1) -> 3 | E10: =COUNTIFS('3-данные'!$A:$A,'3'!$A10,'3-данные'!$H:$H,'3'!E$1) -> 5 | F10: =COUNTIFS('3-данные'!$A:$A,'3'!$A10,'3-данные'!$H:$H,'3'!F$1) -> 9 | G10: =COUNTIFS('3-данные'!$A:$A,'3'!$A10,'3-данные'!$H:$H,'3'!G$1) -> 4 | H10: =COUNTIFS('3-данные'!$A:$A,'3'!$A10,'3-данные'!$H:$H,'3'!H$1) -> 2 | I10: =COUNTIFS('3-данные'!$A:$A,'3'!$A10,'3-данные'!$H:$H,'3'!I$1) -> 7 | ... N10: =COUNTIFS('3-данные'!$A:$A,'3'!$A10,'3-данные'!$H:$H,'3'!N$1) -> 0
A11: Ткаченко Андрей Олегович | B11: =COUNTIFS('3-данные'!$A:$A,'3'!$A11,'3-данные'!$H:$H,'3'!B$1) -> 7 | C11: =COUNTIFS('3-данные'!$A:$A,'3'!$A11,'3-данные'!$H:$H,'3'!C$1) -> 7 | D11: =COUNTIFS('3-данные'!$A:$A,'3'!$A11,'3-данные'!$H:$H,'3'!D$1) -> 7 | E11: =COUNTIFS('3-данные'!$A:$A,'3'!$A11,'3-данные'!$H:$H,'3'!E$1) -> 8 | F11: =COUNTIFS('3-данные'!$A:$A,'3'!$A11,'3-данные'!$H:$H,'3'!F$1) -> 7 | G11: =COUNTIFS('3-данные'!$A:$A,'3'!$A11,'3-данные'!$H:$H,'3'!G$1) -> 4 | H11: =COUNTIFS('3-данные'!$A:$A,'3'!$A11,'3-данные'!$H:$H,'3'!H$1) -> 8 | I11: =COUNTIFS('3-данные'!$A:$A,'3'!$A11,'3-данные'!$H:$H,'3'!I$1) -> 7 | ... N11: =COUNTIFS('3-данные'!$A:$A,'3'!$A11,'3-данные'!$H:$H,'3'!N$1) -> 0
A12: Фролов Сергей Викторович | B12: =COUNTIFS('3-данные'!$A:$A,'3'!$A12,'3-данные'!$H:$H,'3'!B$1) -> 3 | C12: =COUNTIFS('3-данные'!$A:$A,'3'!$A12,'3-данные'!$H:$H,'3'!C$1) -> 7 | D12: =COUNTIFS('3-данные'!$A:$A,'3'!$A12,'3-данные'!$H:$H,'3'!D$1) -> 6 | E12: =COUNTIFS('3-данные'!$A:$A,'3'!$A12,'3-данные'!$H:$H,'3'!E$1) -> 6 | F12: =COUNTIFS('3-данные'!$A:$A,'3'!$A12,'3-данные'!$H:$H,'3'!F$1) -> 9 | G12: =COUNTIFS('3-данные'!$A:$A,'3'!$A12,'3-данные'!$H:$H,'3'!G$1) -> 8 | H12: =COUNTIFS('3-данные'!$A:$A,'3'!$A12,'3-данные'!$H:$H,'3'!H$1) -> 4 | I12: =COUNTIFS('3-данные'!$A:$A,'3'!$A12,'3-данные'!$H:$H,'3'!I$1) -> 6 | ... N12: =COUNTIFS('3-данные'!$A:$A,'3'!$A12,'3-данные'!$H:$H,'3'!N$1) -> 3
A13: Яковлев Артем Игоревич | B13: =COUNTIFS('3-данные'!$A:$A,'3'!$A13,'3-данные'!$H:$H,'3'!B$1) -> 8 | C13: =COUNTIFS('3-данные'!$A:$A,'3'!$A13,'3-данные'!$H:$H,'3'!C$1) -> 6 | D13: =COUNTIFS('3-данные'!$A:$A,'3'!$A13,'3-данные'!$H:$H,'3'!D$1) -> 5 | E13: =COUNTIFS('3-данные'!$A:$A,'3'!$A13,'3-данные'!$H:$H,'3'!E$1) -> 6 | F13: =COUNTIFS('3-данные'!$A:$A,'3'!$A13,'3-данные'!$H:$H,'3'!F$1) -> 9 | G13: =COUNTIFS('3-данные'!$A:$A,'3'!$A13,'3-данные'!$H:$H,'3'!G$1) -> 5 | H13: =COUNTIFS('3-данные'!$A:$A,'3'!$A13,'3-данные'!$H:$H,'3'!H$1) -> 11 | I13: =COUNTIFS('3-данные'!$A:$A,'3'!$A13,'3-данные'!$H:$H,'3'!I$1) -> 9 | ... N13: =COUNTIFS('3-данные'!$A:$A,'3'!$A13,'3-данные'!$H:$H,'3'!N$1) -> 0

Sheet 3-2
A1: ФИО Менеджера (по алфавиту) | B1: 2023-9 | C1: 2023-10 | D1: 2023-11 | E1: 2023-12 | F1: 2024-1 | G1: 2024-2 | H1: 2024-3 | I1: 2024-4 | J1: 2024-5 | K1: 2024-6 | L1: 2024-7 | M1: 2024-8 | N1: 2024-9
A2: Белов Алексей Константинович | B2: =IFERROR((COUNTIFS('3-данные'!$A:$A,'3-2'!$A2,'3-данные'!$H:$H,'3-2'!B$1,'3-данные'!$E:$E,">=9")-COUNTIFS('3-данные'!$A:$A,'3-2'!$A2,'3-данные'!$H:$H,'3-2'!B$1,'3-данные'!$E:$E,">=6"))/COUNTIFS('3-данные'!$A:$A,'3-2'!$A2,'3-данные'!$H:$H,'3-2'!B$1,'3-данные'!$E:$E,">=0"),"") -> -0.5 | C2: =IFERROR((COUNTIFS('3-данные'!$A:$A,'3-2'!$A2,'3-данные'!$H:$H,'3-2'!C$1,'3-данные'!$E:$E,">=9")-COUNTIFS('3-данные'!$A:$A,'3-2'!$A2,'3-данные'!$H:$H,'3-2'!C$1,'3-данные'!$E:$E,">=6"))/COUNTIFS('3-данные'!$A:$A,'3-2'!$A2,'3-данные'!$H:$H,'3-2'!C$1,'3-данные'!$E:$E,">=0"),"") -> -0.85714286 | D2: =IFERROR((COUNTIFS('3-данные'!$A:$A,'3-2'!$A2,'3-данные'!$H:$H,'3-2'!D$1,'3-данные'!$E:$E,">=9")-COUNTIFS('3-данные'!$A:$A,'3-2'!$A2,'3-данные'!$H:$H,'3-2'!D$1,'3-данные'!$E:$E,">=6"))/COUNTIFS('3-данные'!$A:$A,'3-2'!$A2,'3-данные'!$H:$H,'3-2'!D$1,'3-данные'!$E:$E,">=0"),"") -> -0.42857143 | E2: =IFERROR((COUNTIFS('3-данные'!$A:$A,'3-2'!$A2,'3-данные'!$H:$H,'3-2'!E$1,'3-данные'!$E:$E,">=9")-COUNTIFS('3-данные'!$A:$A,'3-2'!$A2,'3-данные'!$H:$H,'3-2'!E$1,'3-данные'!$E:$E,">=6"))/COUNTIFS('3-данные'!$A:$A,'3-2'!$A2,'3-данные'!$H:$H,'3-2'!E$1,'3-данные'!$E:$E,">=0"),"") -> 0 | F2: =IFERROR((COUNTIFS('3-данные'!$A:$A,'3-2'!$A2,'3-данные'!$H:$H,'3-2'!F$1,'3-данные'!$E:$E,">=9")-COUNTIFS('3-данные'!$A:$A,'3-2'!$A2,'3-данные'!$H:$H,'3-2'!F$1,'3-данные'!$E:$E,">=6"))/COUNTIFS('3-данные'!$A:$A,'3-2'!$A2,'3-данные'!$H:$H,'3-2'!F$1,'3-данные'!$E:$E,">=0"),"") -> -0.44444444 | G2: =IFERROR((COUNTIFS('3-данные'!$A:$A,'3-2'!$A2,'3-данные'!$H:$H,'3-2'!G$1,'3-данные'!$E:$E,">=9")-COUNTIFS('3-данные'!$A:$A,'3-2'!$A2,'3-данные'!$H:$H,'3-2'!G$1,'3-данные'!$E:$E,">=6"))/COUNTIFS('3-данные'!$A:$A,'3-2'!$A2,'3-данные'!$H:$H,'3-2'!G$1,'3-данные'!$E:$E,">=0"),"") -> -0.71428571 | H2: =IFERROR((COUNTIFS('3-данные'!$A:$A,'3-2'!$A2,'3-данные'!$H:$H,'3-2'!H$1,'3-данные'!$E:$E,">=9")-COUNTIFS('3-данные'!$A:$A,'3-2'!$A2,'3-данные'!$H:$H,'3-2'!H$1,'3-данные'!$E:$E,">=6"))/COUNTIFS('3-данные'!$A:$A,'3-2'!$A2,'3-данные'!$H:$H,'3-2'!H$1,'3-данные'!$E:$E,">=0"),"") -> -0.45454545 | I2: =IFERROR((COUNTIFS('3-данные'!$A:$A,'3-2'!$A2,'3-данные'!$H:$H,'3-2'!I$1,'3-данные'!$E:$E,">=9")-COUNTIFS('3-данные'!$A:$A,'3-2'!$A2,'3-данные'!$H:$H,'3-2'!I$1,'3-данные'!$E:$E,">=6"))/COUNTIFS('3-данные'!$A:$A,'3-2'!$A2,'3-данные'!$H:$H,'3-2'!I$1,'3-данные'!$E:$E,">=0"),"") -> -0.71428571 | ... N2: =IFERROR((COUNTIFS('3-данные'!$A:$A,'3-2'!$A2,'3-данные'!$H:$H,'3-2'!N$1,'3-данные'!$E:$E,">=9")-COUNTIFS('3-данные'!$A:$A,'3-2'!$A2,'3-данные'!$H:$H,'3-2'!N$1,'3-данные'!$E:$E,">=6"))/COUNTIFS('3-данные'!$A:$A,'3-2'!$A2,'3-данные'!$H:$H,'3-2'!N$1,'3-данные'!$E:$E,">=0"),"")
A3: Громова Мария Ильинична | B3: =IFERROR((COUNTIFS('3-данные'!$A:$A,'3-2'!$A3,'3-данные'!$H:$H,'3-2'!B$1,'3-данные'!$E:$E,">=9")-COUNTIFS('3-данные'!$A:$A,'3-2'!$A3,'3-данные'!$H:$H,'3-2'!B$1,'3-данные'!$E:$E,">=6"))/COUNTIFS('3-данные'!$A:$A,'3-2'!$A3,'3-данные'!$H:$H,'3-2'!B$1,'3-данные'!$E:$E,">=0"),"") -> -0.4 | C3: =IFERROR((COUNTIFS('3-данные'!$A:$A,'3-2'!$A3,'3-данные'!$H:$H,'3-2'!C$1,'3-данные'!$E:$E,">=9")-COUNTIFS('3-данные'!$A:$A,'3-2'!$A3,'3-данные'!$H:$H,'3-2'!C$1,'3-данные'!$E:$E,">=6"))/COUNTIFS('3-данные'!$A:$A,'3-2'!$A3,'3-данные'!$H:$H,'3-2'!C$1,'3-данные'!$E:$E,">=0"),"") -> -0.42857143 | D3: =IFERROR((COUNTIFS('3-данные'!$A:$A,'3-2'!$A3,'3-данные'!$H:$H,'3-2'!D$1,'3-данные'!$E:$E,">=9")-COUNTIFS('3-данные'!$A:$A,'3-2'!$A3,'3-данные'!$H:$H,'3-2'!D$1,'3-данные'!$E:$E,">=6"))/COUNTIFS('3-данные'!$A:$A,'3-2'!$A3,'3-данные'!$H:$H,'3-2'!D$1,'3-данные'!$E:$E,">=0"),"") -> -0.57142857 | E3: =IFERROR((COUNTIFS('3-данные'!$A:$A,'3-2'!$A3,'3-данные'!$H:$H,'3-2'!E$1,'3-данные'!$E:$E,">=9")-COUNTIFS('3-данные'!$A:$A,'3-2'!$A3,'3-данные'!$H:$H,'3-2'!E$1,'3-данные'!$E:$E,">=6"))/COUNTIFS('3-данные'!$A:$A,'3-2'!$A3,'3-данные'!$H:$H,'3-2'!E$1,'3-данные'!$E:$E,">=0"),"") -> -0.66666667 | F3: =IFERROR((COUNTIFS('3-данные'!$A:$A,'3-2'!$A3,'3-данные'!$H:$H,'3-2'!F$1,'3-данные'!$E:$E,">=9")-COUNTIFS('3-данные'!$A:$A,'3-2'!$A3,'3-данные'!$H:$H,'3-2'!F$1,'3-данные'!$E:$E,">=6"))/COUNTIFS('3-данные'!$A:$A,'3-2'!$A3,'3-данные'!$H:$H,'3-2'!F$1,'3-данные'!$E:$E,">=0"),"") -> -0.33333333 | G3: =IFERROR((COUNTIFS('3-данные'!$A:$A,'3-2'!$A3,'3-данные'!$H:$H,'3-2'!G$1,'3-данные'!$E:$E,">=9")-COUNTIFS('3-данные'!$A:$A,'3-2'!$A3,'3-данные'!$H:$H,'3-2'!G$1,'3-данные'!$E:$E,">=6"))/COUNTIFS('3-данные'!$A:$A,'3-2'!$A3,'3-данные'!$H:$H,'3-2'!G$1,'3-данные'!$E:$E,">=0"),"") -> -0.4 | H3: =IFERROR((COUNTIFS('3-данные'!$A:$A,'3-2'!$A3,'3-данные'!$H:$H,'3-2'!H$1,'3-данные'!$E:$E,">=9")-COUNTIFS('3-данные'!$A:$A,'3-2'!$A3,'3-данные'!$H:$H,'3-2'!H$1,'3-данные'!$E:$E,">=6"))/COUNTIFS('3-данные'!$A:$A,'3-2'!$A3,'3-данные'!$H:$H,'3-2'!H$1,'3-данные'!$E:$E,">=0"),"") -> -0.36363636 | I3: =IFERROR((COUNTIFS('3-данные'!$A:$A,'3-2'!$A3,'3-данные'!$H:$H,'3-2'!I$1,'3-данные'!$E:$E,">=9")-COUNTIFS('3-данные'!$A:$A,'3-2'!$A3,'3-данные'!$H:$H,'3-2'!I$1,'3-данные'!$E:$E,">=6"))/COUNTIFS('3-данные'!$A:$A,'3-2'!$A3,'3-данные'!$H:$H,'3-2'!I$1,'3-данные'!$E:$E,">=0"),"") -> -0.4 | ... N3: =IFERROR((COUNTIFS('3-данные'!$A:$A,'3-2'!$A3,'3-данные'!$H:$H,'3-2'!N$1,'3-данные'!$E:$E,">=9")-COUNTIFS('3-данные'!$A:$A,'3-2'!$A3,'3-данные'!$H:$H,'3-2'!N$1,'3-данные'!$E:$E,">=6"))/COUNTIFS('3-данные'!$A:$A,'3-2'!$A3,'3-данные'!$H:$H,'3-2'!N$1,'3-данные'!$E:$E,">=0"),"")
A4: Иванова Анна Сергеевна | B4: =IFERROR((COUNTIFS('3-данные'!$A:$A,'3-2'!$A4,'3-данные'!$H:$H,'3-2'!B$1,'3-данные'!$E:$E,">=9")-COUNTIFS('3-данные'!$A:$A,'3-2'!$A4,'3-данные'!$H:$H,'3-2'!B$1,'3-данные'!$E:$E,">=6"))/COUNTIFS('3-данные'!$A:$A,'3-2'!$A4,'3-данные'!$H:$H,'3-2'!B$1,'3-данные'!$E:$E,">=0"),"") -> -1 | C4: =IFERROR((COUNTIFS('3-данные'!$A:$A,'3-2'!$A4,'3-данные'!$H:$H,'3-2'!C$1,'3-данные'!$E:$E,">=9")-COUNTIFS('3-данные'!$A:$A,'3-2'!$A4,'3-данные'!$H:$H,'3-2'!C$1,'3-данные'!$E:$E,">=6"))/COUNTIFS('3-данные'!$A:$A,'3-2'!$A4,'3-данные'!$H:$H,'3-2'!C$1,'3-данные'!$E:$E,">=0"),"") -> -0.45454545 | D4: =IFERROR((COUNTIFS('3-данные'!$A:$A,'3-2'!$A4,'3-данные'!$H:$H,'3-2'!D$1,'3-данные'!$E:$E,">=9")-COUNTIFS('3-данные'!$A:$A,'3-2'!$A4,'3-данные'!$H:$H,'3-2'!D$1,'3-данные'!$E:$E,">=6"))/COUNTIFS('3-данные'!$A:$A,'3-2'!$A4,'3-данные'!$H:$H,'3-2'!D$1,'3-данные'!$E:$E,">=0"),"") -> -0.5 | E4: =IFERROR((COUNTIFS('3-данные'!$A:$A,'3-2'!$A4,'3-данные'!$H:$H,'3-2'!E$1,'3-данные'!$E:$E,">=9")-COUNTIFS('3-данные'!$A:$A,'3-2'!$A4,'3-данные'!$H:$H,'3-2'!E$1,'3-данные'!$E:$E,">=6"))/COUNTIFS('3-данные'!$A:$A,'3-2'!$A4,'3-данные'!$H:$H,'3-2'!E$1,'3-данные'!$E:$E,">=0"),"") -> -0.33333333 | F4: =IFERROR((COUNTIFS('3-данные'!$A:$A,'3-2'!$A4,'3-данные'!$H:$H,'3-2'!F$1,'3-данные'!$E:$E,">=9")-COUNTIFS('3-данные'!$A:$A,'3-2'!$A4,'3-данные'!$H:$H,'3-2'!F$1,'3-данные'!$E:$E,">=6"))/COUNTIFS('3-данные'!$A:$A,'3-2'!$A4,'3-данные'!$H:$H,'3-2'!F$1,'3-данные'!$E:$E,">=0"),"") -> -0.57142857 | G4: =IFERROR((COUNTIFS('3-данные'!$A:$A,'3-2'!$A4,'3-данные'!$H:$H,'3-2'!G$1,'3-данные'!$E:$E,">=9")-COUNTIFS('3-данные'!$A:$A,'3-2'!$A4,'3-данные'!$H:$H,'3-2'!G$1,'3-данные'!$E:$E,">=6"))/COUNTIFS('3-данные'!$A:$A,'3-2'!$A4,'3-данные'!$H:$H,'3-2'!G$1,'3-данные'!$E:$E,">=0"),"") -> -0.71428571 | H4: =IFERROR((COUNTIFS('3-данные'!$A:$A,'3-2'!$A4,'3-данные'!$H:$H,'3-2'!H$1,'3-данные'!$E:$E,">=9")-COUNTIFS('3-данные'!$A:$A,'3-2'!$A4,'3-данные'!$H:$H,'3-2'!H$1,'3-данные'!$E:$E,">=6"))/COUNTIFS('3-данные'!$A:$A,'3-2'!$A4,'3-данные'!$H:$H,'3-2'!H$1,'3-данные'!$E:$E,">=0"),"") -> -1 | I4: =IFERROR((COUNTIFS('3-данные'!$A:$A,'3-2'!$A4,'3-данные'!$H:$H,'3-2'!I$1,'3-данные'!$E:$E,">=9")-COUNTIFS('3-данные'!$A:$A,'3-2'!$A4,'3-данные'!$H:$H,'3-2'!I$1,'3-данные'!$E:$E,">=6"))/COUNTIFS('3-данные'!$A:$A,'3-2'!$A4,'3-данные'!$H:$H,'3-2'!I$1,'3-данные'!$E:$E,">=0"),"") -> -0.66666667 | ... N4: =IFERROR((COUNTIFS('3-данные'!$A:$A,'3-2'!$A4,'3-данные'!$H:$H,'3-2'!N$1,'3-данные'!$E:$E,">=9")-COUNTIFS('3-данные'!$A:$A,'3-2'!$A4,'3-данные'!$H:$H,'3-2'!N$1,'3-данные'!$E:$E,">=6"))/COUNTIFS('3-данные'!$A:$A,'3-2'!$A4,'3-данные'!$H:$H,'3-2'!N$1,'3-данные'!$E:$E,">=0"),"")
A5: Кузнецов Дмитрий Львович | B5: =IFERROR((COUNTIFS('3-данные'!$A:$A,'3-2'!$A5,'3-данные'!$H:$H,'3-2'!B$1,'3-данные'!$E:$E,">=9")-COUNTIFS('3-данные'!$A:$A,'3-2'!$A5,'3-данные'!$H:$H,'3-2'!B$1,'3-данные'!$E:$E,">=6"))/COUNTIFS('3-данные'!$A:$A,'3-2'!$A5,'3-данные'!$H:$H,'3-2'!B$1,'3-данные'!$E:$E,">=0"),"") -> -0.4 | C5: =IFERROR((COUNTIFS('3-данные'!$A:$A,'3-2'!$A5,'3-данные'!$H:$H,'3-2'!C$1,'3-данные'!$E:$E,">=9")-COUNTIFS('3-данные'!$A:$A,'3-2'!$A5,'3-данные'!$H:$H,'3-2'!C$1,'3-данные'!$E:$E,">=6"))/COUNTIFS('3-данные'!$A:$A,'3-2'!$A5,'3-данные'!$H:$H,'3-2'!C$1,'3-данные'!$E:$E,">=0"),"") -> -0.44444444 | D5: =IFERROR((COUNTIFS('3-данные'!$A:$A,'3-2'!$A5,'3-данные'!$H:$H,'3-2'!D$1,'3-данные'!$E:$E,">=9")-COUNTIFS('3-данные'!$A:$A,'3-2'!$A5,'3-данные'!$H:$H,'3-2'!D$1,'3-данные'!$E:$E,">=6"))/COUNTIFS('3-данные'!$A:$A,'3-2'!$A5,'3-данные'!$H:$H,'3-2'!D$1,'3-данные'!$E:$E,">=0"),"") -> -0.5 | E5: =IFERROR((COUNTIFS('3-данные'!$A:$A,'3-2'!$A5,'3-данные'!$H:$H,'3-2'!E$1,'3-данные'!$E:$E,">=9")-COUNTIFS('3-данные'!$A:$A,'3-2'!$A5,'3-данные'!$H:$H,'3-2'!E$1,'3-данные'!$E:$E,">=6"))/COUNTIFS('3-данные'!$A:$A,'3-2'!$A5,'3-данные'!$H:$H,'3-2'!E$1,'3-данные'!$E:$E,">=0"),"") -> -0.6 | F5: =IFERROR((COUNTIFS('3-данные'!$A:$A,'3-2'!$A5,'3-данные'!$H:$H,'3-2'!F$1,'3-данные'!$E:$E,">=9")-COUNTIFS('3-данные'!$A:$A,'3-2'!$A5,'3-данные'!$H:$H,'3-2'!F$1,'3-данные'!$E:$E,">=6"))/COUNTIFS('3-данные'!$A:$A,'3-2'!$A5,'3-данные'!$H:$H,'3-2'!F$1,'3-данные'!$E:$E,">=0"),"") -> -0.7 | G5: =IFERROR((COUNTIFS('3-данные'!$A:$A,'3-2'!$A5,'3-данные'!$H:$H,'3-2'!G$1,'3-данные'!$E:$E,">=9")-COUNTIFS('3-данные'!$A:$A,'3-2'!$A5,'3-данные'!$H:$H,'3-2'!G$1,'3-данные'!$E:$E,">=6"))/COUNTIFS('3-данные'!$A:$A,'3-2'!$A5,'3-данные'!$H:$H,'3-2'!G$1,'3-данные'!$E:$E,">=0"),"") -> -0.375 | H5: =IFERROR((COUNTIFS('3-данные'!$A:$A,'3-2'!$A5,'3-данные'!$H:$H,'3-2'!H$1,'3-данные'!$E:$E,">=9")-COUNTIFS('3-данные'!$A:$A,'3-2'!$A5,'3-данные'!$H:$H,'3-2'!H$1,'3-данные'!$E:$E,">=6"))/COUNTIFS('3-данные'!$A:$A,'3-2'!$A5,'3-данные'!$H:$H,'3-2'!H$1,'3-данные'!$E:$E,">=0"),"") -> -0.5 | I5: =IFERROR((COUNTIFS('3-данные'!$A:$A,'3-2'!$A5,'3-данные'!$H:$H,'3-2'!I$1,'3-данные'!$E:$E,">=9")-COUNTIFS('3-данные'!$A:$A,'3-2'!$A5,'3-данные'!$H:$H,'3-2'!I$1,'3-данные'!$E:$E,">=6"))/COUNTIFS('3-данные'!$A:$A,'3-2'!$A5,'3-данные'!$H:$H,'3-2'!I$1,'3-данные'!$E:$E,">=0"),"") -> -0.71428571 | ... N5: =IFERROR((COUNTIFS('3-данные'!$A:$A,'3-2'!$A5,'3-данные'!$H:$H,'3-2'!N$1,'3-данные'!$E:$E,">=9")-COUNTIFS('3-данные'!$A:$A,'3-2'!$A5,'3-данные'!$H:$H,'3-2'!N$1,'3-данные'!$E:$E,">=6"))/COUNTIFS('3-данные'!$A:$A,'3-2'!$A5,'3-данные'!$H:$H,'3-2'!N$1,'3-данные'!$E:$E,">=0"),"")
A6: Новикова Ольга Петровна | B6: =IFERROR((COUNTIFS('3-данные'!$A:$A,'3-2'!$A6,'3-данные'!$H:$H,'3-2'!B$1,'3-данные'!$E:$E,">=9")-COUNTIFS('3-данные'!$A:$A,'3-2'!$A6,'3-данные'!$H:$H,'3-2'!B$1,'3-данные'!$E:$E,">=6"))/COUNTIFS('3-данные'!$A:$A,'3-2'!$A6,'3-данные'!$H:$H,'3-2'!B$1,'3-данные'!$E:$E,">=0"),"") -> -0.375 | C6: =IFERROR((COUNTIFS('3-данные'!$A:$A,'3-2'!$A6,'3-данные'!$H:$H,'3-2'!C$1,'3-данные'!$E:$E,">=9")-COUNTIFS('3-данные'!$A:$A,'3-2'!$A6,'3-данные'!$H:$H,'3-2'!C$1,'3-данные'!$E:$E,">=6"))/COUNTIFS('3-данные'!$A:$A,'3-2'!$A6,'3-данные'!$H:$H,'3-2'!C$1,'3-данные'!$E:$E,">=0"),"") -> -0.4 | D6: =IFERROR((COUNTIFS('3-данные'!$A:$A,'3-2'!$A6,'3-данные'!$H:$H,'3-2'!D$1,'3-данные'!$E:$E,">=9")-COUNTIFS('3-данные'!$A:$A,'3-2'!$A6,'3-данные'!$H:$H,'3-2'!D$1,'3-данные'!$E:$E,">=6"))/COUNTIFS('3-данные'!$A:$A,'3-2'!$A6,'3-данные'!$H:$H,'3-2'!D$1,'3-данные'!$E:$E,">=0"),"") -> -0.33333333 | E6: =IFERROR((COUNTIFS('3-данные'!$A:$A,'3-2'!$A6,'3-данные'!$H:$H,'3-2'!E$1,'3-данные'!$E:$E,">=9")-COUNTIFS('3-данные'!$A:$A,'3-2'!$A6,'3-данные'!$H:$H,'3-2'!E$1,'3-данные'!$E:$E,">=6"))/COUNTIFS('3-данные'!$A:$A,'3-2'!$A6,'3-данные'!$H:$H,'3-2'!E$1,'3-данные'!$E:$E,">=0"),"") -> -0.6 | F6: =IFERROR((COUNTIFS('3-данные'!$A:$A,'3-2'!$A6,'3-данные'!$H:$H,'3-2'!F$1,'3-данные'!$E:$E,">=9")-COUNTIFS('3-данные'!$A:$A,'3-2'!$A6,'3-данные'!$H:$H,'3-2'!F$1,'3-данные'!$E:$E,">=6"))/COUNTIFS('3-данные'!$A:$A,'3-2'!$A6,'3-данные'!$H:$H,'3-2'!F$1,'3-данные'!$E:$E,">=0"),"") -> -0.57142857 | G6: =IFERROR((COUNTIFS('3-данные'!$A:$A,'3-2'!$A6,'3-данные'!$H:$H,'3-2'!G$1,'3-данные'!$E:$E,">=9")-COUNTIFS('3-данные'!$A:$A,'3-2'!$A6,'3-данные'!$H:$H,'3-2'!G$1,'3-данные'!$E:$E,">=6"))/COUNTIFS('3-данные'!$A:$A,'3-2'!$A6,'3-данные'!$H:$H,'3-2'!G$1,'3-данные'!$E:$E,">=0"),"") -> -0.75 | H6: =IFERROR((COUNTIFS('3-данные'!$A:$A,'3-2'!$A6,'3-данные'!$H:$H,'3-2'!H$1,'3-данные'!$E:$E,">=9")-COUNTIFS('3-данные'!$A:$A,'3-2'!$A6,'3-данные'!$H:$H,'3-2'!H$1,'3-данные'!$E:$E,">=6"))/COUNTIFS('3-данные'!$A:$A,'3-2'!$A6,'3-данные'!$H:$H,'3-2'!H$1,'3-данные'!$E:$E,">=0"),"") -> -0.8 | I6: =IFERROR((COUNTIFS('3-данные'!$A:$A,'3-2'!$A6,'3-данные'!$H:$H,'3-2'!I$1,'3-данные'!$E:$E,">=9")-COUNTIFS('3-данные'!$A:$A,'3-2'!$A6,'3-данные'!$H:$H,'3-2'!I$1,'3-данные'!$E:$E,">=6"))/COUNTIFS('3-данные'!$A:$A,'3-2'!$A6,'3-данные'!$H:$H,'3-2'!I$1,'3-данные'!$E:$E,">=0"),"") -> -0.57142857 | ... N6: =IFERROR((COUNTIFS('3-данные'!$A:$A,'3-2'!$A6,'3-данные'!$H:$H,'3-2'!N$1,'3-данные'!$E:$E,">=9")-COUNTIFS('3-данные'!$A:$A,'3-2'!$A6,'3-данные'!$H:$H,'3-2'!N$1,'3-данные'!$E:$E,">=6"))/COUNTIFS('3-данные'!$A:$A,'3-2'!$A6,'3-данные'!$H:$H,'3-2'!N$1,'3-данные'!$E:$E,">=0"),"") -> 0
A7: Орлов Павел Денисович | B7: =IFERROR((COUNTIFS('3-данные'!$A:$A,'3-2'!$A7,'3-данные'!$H:$H,'3-2'!B$1,'3-данные'!$E:$E,">=9")-COUNTIFS('3-данные'!$A:$A,'3-2'!$A7,'3-данные'!$H:$H,'3-2'!B$1,'3-данные'!$E:$E,">=6"))/COUNTIFS('3-данные'!$A:$A,'3-2'!$A7,'3-данные'!$H:$H,'3-2'!B$1,'3-данные'!$E:$E,">=0"),"") -> -0.625 | C7: =IFERROR((COUNTIFS('3-данные'!$A:$A,'3-2'!$A7,'3-данные'!$H:$H,'3-2'!C$1,'3-данные'!$E:$E,">=9")-COUNTIFS('3-данные'!$A:$A,'3-2'!$A7,'3-данные'!$H:$H,'3-2'!C$1,'3-данные'!$E:$E,">=6"))/COUNTIFS('3-данные'!$A:$A,'3-2'!$A7,'3-данные'!$H:$H,'3-2'!C$1,'3-данные'!$E:$E,">=0"),"") -> -0.4 | D7: =IFERROR((COUNTIFS('3-данные'!$A:$A,'3-2'!$A7,'3-данные'!$H:$H,'3-2'!D$1,'3-данные'!$E:$E,">=9")-COUNTIFS('3-данные'!$A:$A,'3-2'!$A7,'3-данные'!$H:$H,'3-2'!D$1,'3-данные'!$E:$E,">=6"))/COUNTIFS('3-данные'!$A:$A,'3-2'!$A7,'3-данные'!$H:$H,'3-2'!D$1,'3-данные'!$E:$E,">=0"),"") -> -0.66666667 | E7: =IFERROR((COUNTIFS('3-данные'!$A:$A,'3-2'!$A7,'3-данные'!$H:$H,'3-2'!E$1,'3-данные'!$E:$E,">=9")-COUNTIFS('3-данные'!$A:$A,'3-2'!$A7,'3-данные'!$H:$H,'3-2'!E$1,'3-данные'!$E:$E,">=6"))/COUNTIFS('3-данные'!$A:$A,'3-2'!$A7,'3-данные'!$H:$H,'3-2'!E$1,'3-данные'!$E:$E,">=0"),"") -> -0.58333333 | F7: =IFERROR((COUNTIFS('3-данные'!$A:$A,'3-2'!$A7,'3-данные'!$H:$H,'3-2'!F$1,'3-данные'!$E:$E,">=9")-COUNTIFS('3-данные'!$A:$A,'3-2'!$A7,'3-данные'!$H:$H,'3-2'!F$1,'3-данные'!$E:$E,">=6"))/COUNTIFS('3-данные'!$A:$A,'3-2'!$A7,'3-данные'!$H:$H,'3-2'!F$1,'3-данные'!$E:$E,">=0"),"") -> -0.66666667 | G7: =IFERROR((COUNTIFS('3-данные'!$A:$A,'3-2'!$A7,'3-данные'!$H:$H,'3-2'!G$1,'3-данные'!$E:$E,">=9")-COUNTIFS('3-данные'!$A:$A,'3-2'!$A7,'3-данные'!$H:$H,'3-2'!G$1,'3-данные'!$E:$E,">=6"))/COUNTIFS('3-данные'!$A:$A,'3-2'!$A7,'3-данные'!$H:$H,'3-2'!G$1,'3-данные'!$E:$E,">=0"),"") -> -0.33333333 | H7: =IFERROR((COUNTIFS('3-данные'!$A:$A,'3-2'!$A7,'3-данные'!$H:$H,'3-2'!H$1,'3-данные'!$E:$E,">=9")-COUNTIFS('3-данные'!$A:$A,'3-2'!$A7,'3-данные'!$H:$H,'3-2'!H$1,'3-данные'!$E:$E,">=6"))/COUNTIFS('3-данные'!$A:$A,'3-2'!$A7,'3-данные'!$H:$H,'3-2'!H$1,'3-данные'!$E:$E,">=0"),"") -> -0.625 | I7: =IFERROR((COUNTIFS('3-данные'!$A:$A,'3-2'!$A7,'3-данные'!$H:$H,'3-2'!I$1,'3-данные'!$E:$E,">=9")-COUNTIFS('3-данные'!$A:$A,'3-2'!$A7,'3-данные'!$H:$H,'3-2'!I$1,'3-данные'!$E:$E,">=6"))/COUNTIFS('3-данные'!$A:$A,'3-2'!$A7,'3-данные'!$H:$H,'3-2'!I$1,'3-данные'!$E:$E,">=0"),"") -> -0.28571429 | ... N7: =IFERROR((COUNTIFS('3-данные'!$A:$A,'3-2'!$A7,'3-данные'!$H:$H,'3-2'!N$1,'3-данные'!$E:$E,">=9")-COUNTIFS('3-данные'!$A:$A,'3-2'!$A7,'3-данные'!$H:$H,'3-2'!N$1,'3-данные'!$E:$E,">=6"))/COUNTIFS('3-данные'!$A:$A,'3-2'!$A7,'3-данные'!$H:$H,'3-2'!N$1,'3-данные'!$E:$E,">=0"),"")
A8: Петров Владимир Кириллович | B8: =IFERROR((COUNTIFS('3-данные'!$A:$A,'3-2'!$A8,'3-данные'!$H:$H,'3-2'!B$1,'3-данные'!$E:$E,">=9")-COUNTIFS('3-данные'!$A:$A,'3-2'!$A8,'3-данные'!$H:$H,'3-2'!B$1,'3-данные'!$E:$E,">=6"))/COUNTIFS('3-данные'!$A:$A,'3-2'!$A8,'3-данные'!$H:$H,'3-2'!B$1,'3-данные'!$E:$E,">=0"),"") -> -0.77777778 | C8: =IFERROR((COUNTIFS('3-данные'!$A:$A,'3-2'!$A8,'3-данные'!$H:$H,'3-2'!C$1,'3-данные'!$E:$E,">=9")-COUNTIFS('3-данные'!$A:$A,'3-2'!$A8,'3-данные'!$H:$H,'3-2'!C$1,'3-данные'!$E:$E,">=6"))/COUNTIFS('3-данные'!$A:$A,'3-2'!$A8,'3-данные'!$H:$H,'3-2'!C$1,'3-данные'!$E:$E,">=0"),"") -> -0.57142857 | D8: =IFERROR((COUNTIFS('3-данные'!$A:$A,'3-2'!$A8,'3-данные'!$H:$H,'3-2'!D$1,'3-данные'!$E:$E,">=9")-COUNTIFS('3-данные'!$A:$A,'3-2'!$A8,'3-данные'!$H:$H,'3-2'!D$1,'3-данные'!$E:$E,">=6"))/COUNTIFS('3-данные'!$A:$A,'3-2'!$A8,'3-данные'!$H:$H,'3-2'!D$1,'3-данные'!$E:$E,">=0"),"") -> -0.6 | E8: =IFERROR((COUNTIFS('3-данные'!$A:$A,'3-2'!$A8,'3-данные'!$H:$H,'3-2'!E$1,'3-данные'!$E:$E,">=9")-COUNTIFS('3-данные'!$A:$A,'3-2'!$A8,'3-данные'!$H:$H,'3-2'!E$1,'3-данные'!$E:$E,">=6"))/COUNTIFS('3-данные'!$A:$A,'3-2'!$A8,'3-данные'!$H:$H,'3-2'!E$1,'3-данные'!$E:$E,">=0"),"") -> -0.5 | F8: =IFERROR((COUNTIFS('3-данные'!$A:$A,'3-2'!$A8,'3-данные'!$H:$H,'3-2'!F$1,'3-данные'!$E:$E,">=9")-COUNTIFS('3-данные'!$A:$A,'3-2'!$A8,'3-данные'!$H:$H,'3-2'!F$1,'3-данные'!$E:$E,">=6"))/COUNTIFS('3-данные'!$A:$A,'3-2'!$A8,'3-данные'!$H:$H,'3-2'!F$1,'3-данные'!$E:$E,">=0"),"") -> -0.75 | G8: =IFERROR((COUNTIFS('3-данные'!$A:$A,'3-2'!$A8,'3-данные'!$H:$H,'3-2'!G$1,'3-данные'!$E:$E,">=9")-COUNTIFS('3-данные'!$A:$A,'3-2'!$A8,'3-данные'!$H:$H,'3-2'!G$1,'3-данные'!$E:$E,">=6"))/COUNTIFS('3-данные'!$A:$A,'3-2'!$A8,'3-данные'!$H:$H,'3-2'!G$1,'3-данные'!$E:$E,">=0"),"") -> -0.33333333 | H8: =IFERROR((COUNTIFS('3-данные'!$A:$A,'3-2'!$A8,'3-данные'!$H:$H,'3-2'!H$1,'3-данные'!$E:$E,">=9")-COUNTIFS('3-данные'!$A:$A,'3-2'!$A8,'3-данные'!$H:$H,'3-2'!H$1,'3-данные'!$E:$E,">=6"))/COUNTIFS('3-данные'!$A:$A,'3-2'!$A8,'3-данные'!$H:$H,'3-2'!H$1,'3-данные'!$E:$E,">=0"),"") -> -0.5 | I8: =IFERROR((COUNTIFS('3-данные'!$A:$A,'3-2'!$A8,'3-данные'!$H:$H,'3-2'!I$1,'3-данные'!$E:$E,">=9")-COUNTIFS('3-данные'!$A:$A,'3-2'!$A8,'3-данные'!$H:$H,'3-2'!I$1,'3-данные'!$E:$E,">=6"))/COUNTIFS('3-данные'!$A:$A,'3-2'!$A8,'3-данные'!$H:$H,'3-2'!I$1,'3-данные'!$E:$E,">=0"),"") -> -0.625 | ... N8: =IFERROR((COUNTIFS('3-данные'!$A:$A,'3-2'!$A8,'3-данные'!$H:$H,'3-2'!N$1,'3-данные'!$E:$E,">=9")-COUNTIFS('3-данные'!$A:$A,'3-2'!$A8,'3-данные'!$H:$H,'3-2'!N$1,'3-данные'!$E:$E,">=6"))/COUNTIFS('3-данные'!$A:$A,'3-2'!$A8,'3-данные'!$H:$H,'3-2'!N$1,'3-данные'!$E:$E,">=0"),"") -> -1
A9: Семенова Ирина Валерьевна | B9: =IFERROR((COUNTIFS('3-данные'!$A:$A,'3-2'!$A9,'3-данные'!$H:$H,'3-2'!B$1,'3-данные'!$E:$E,">=9")-COUNTIFS('3-данные'!$A:$A,'3-2'!$A9,'3-данные'!$H:$H,'3-2'!B$1,'3-данные'!$E:$E,">=6"))/COUNTIFS('3-данные'!$A:$A,'3-2'!$A9,'3-данные'!$H:$H,'3-2'!B$1,'3-данные'!$E:$E,">=0"),"") -> -0.25 | C9: =IFERROR((COUNTIFS('3-данные'!$A:$A,'3-2'!$A9,'3-данные'!$H:$H,'3-2'!C$1,'3-данные'!$E:$E,">=9")-COUNTIFS('3-данные'!$A:$A,'3-2'!$A9,'3-данные'!$H:$H,'3-2'!C$1,'3-данные'!$E:$E,">=6"))/COUNTIFS('3-данные'!$A:$A,'3-2'!$A9,'3-данные'!$H:$H,'3-2'!C$1,'3-данные'!$E:$E,">=0"),"") -> -0.28571429 | D9: =IFERROR((COUNTIFS('3-данные'!$A:$A,'3-2'!$A9,'3-данные'!$H:$H,'3-2'!D$1,'3-данные'!$E:$E,">=9")-COUNTIFS('3-данные'!$A:$A,'3-2'!$A9,'3-данные'!$H:$H,'3-2'!D$1,'3-данные'!$E:$E,">=6"))/COUNTIFS('3-данные'!$A:$A,'3-2'!$A9,'3-данные'!$H:$H,'3-2'!D$1,'3-данные'!$E:$E,">=0"),"") -> -0.75 | E9: =IFERROR((COUNTIFS('3-данные'!$A:$A,'3-2'!$A9,'3-данные'!$H:$H,'3-2'!E$1,'3-данные'!$E:$E,">=9")-COUNTIFS('3-данные'!$A:$A,'3-2'!$A9,'3-данные'!$H:$H,'3-2'!E$1,'3-данные'!$E:$E,">=6"))/COUNTIFS('3-данные'!$A:$A,'3-2'!$A9,'3-данные'!$H:$H,'3-2'!E$1,'3-данные'!$E:$E,">=0"),"") -> -0.25 | F9: =IFERROR((COUNTIFS('3-данные'!$A:$A,'3-2'!$A9,'3-данные'!$H:$H,'3-2'!F$1,'3-данные'!$E:$E,">=9")-COUNTIFS('3-данные'!$A:$A,'3-2'!$A9,'3-данные'!$H:$H,'3-2'!F$1,'3-данные'!$E:$E,">=6"))/COUNTIFS('3-данные'!$A:$A,'3-2'!$A9,'3-данные'!$H:$H,'3-2'!F$1,'3-данные'!$E:$E,">=0"),"") -> -0.66666667 | G9: =IFERROR((COUNTIFS('3-данные'!$A:$A,'3-2'!$A9,'3-данные'!$H:$H,'3-2'!G$1,'3-данные'!$E:$E,">=9")-COUNTIFS('3-данные'!$A:$A,'3-2'!$A9,'3-данные'!$H:$H,'3-2'!G$1,'3-данные'!$E:$E,">=6"))/COUNTIFS('3-данные'!$A:$A,'3-2'!$A9,'3-данные'!$H:$H,'3-2'!G$1,'3-данные'!$E:$E,">=0"),"") -> -0.55555556 | H9: =IFERROR((COUNTIFS('3-данные'!$A:$A,'3-2'!$A9,'3-данные'!$H:$H,'3-2'!H$1,'3-данные'!$E:$E,">=9")-COUNTIFS('3-данные'!$A:$A,'3-2'!$A9,'3-данные'!$H:$H,'3-2'!H$1,'3-данные'!$E:$E,">=6"))/COUNTIFS('3-данные'!$A:$A,'3-2'!$A9,'3-данные'!$H:$H,'3-2'!H$1,'3-данные'!$E:$E,">=0"),"") -> -0.5 | I9: =IFERROR((COUNTIFS('3-данные'!$A:$A,'3-2'!$A9,'3-данные'!$H:$H,'3-2'!I$1,'3-данные'!$E:$E,">=9")-COUNTIFS('3-данные'!$A:$A,'3-2'!$A9,'3-данные'!$H:$H,'3-2'!I$1,'3-данные'!$E:$E,">=6"))/COUNTIFS('3-данные'!$A:$A,'3-2'!$A9,'3-данные'!$H:$H,'3-2'!I$1,'3-данные'!$E:$E,">=0"),"") -> -0.75 | ... N9: =IFERROR((COUNTIFS('3-данные'!$A:$A,'3-2'!$A9,'3-данные'!$H:$H,'3-2'!N$1,'3-данные'!$E:$E,">=9")-COUNTIFS('3-данные'!$A:$A,'3-2'!$A9,'3-данные'!$H:$H,'3-2'!N$1,'3-данные'!$E:$E,">=6"))/COUNTIFS('3-данные'!$A:$A,'3-2'!$A9,'3-данные'!$H:$H,'3-2'!N$1,'3-данные'!$E:$E,">=0"),"")
